# 30. More on Exceptions

## Exception Handling

Exception handling is particularly useful when dealing with user input. For example, in a program that requests user input of two numbers and then outputs their division, you need to handle cases where division by zero might occur if the user enters 0 as the second number.

```cpp
#include <iostream>
using namespace std;

int main() {
    int num1;
    cout << "Enter the first number: ";
    cin >> num1;
    
    int num2;
    cout << "Enter the second number: ";
    cin >> num2;
    
    cout << "Result: " << num1 / num2;
}
```

This program works perfectly if the user enters any number besides 0. However, if the user enters 0, the program crashes. We need to handle that input.

Fill in the blanks to declare an integer variable `myVar` and enter a number value into it:

```cpp
int myVar;
cin >> myVar;
```

## Throwing Exceptions

In the event that the second number is equal to 0, we need to throw an exception.

```cpp
#include <iostream>
using namespace std;

int main() {
    int num1;
    cout << "Enter the first number: ";
    cin >> num1;
    
    int num2;
    cout << "Enter the second number: ";
    cin >> num2;
    
    if (num2 == 0) {
        throw 0;
    }
    
    cout << "Result: " << num1 / num2;  
}
```

This code throws an exception with the code `0` of type integer. Next, we'll use the `try/catch` block to handle this exception.

## Handling Exceptions with Try/Catch

Now we need to handle the thrown exception using a `try/catch` block.

```cpp
#include <iostream>
using namespace std;

int main() {
    try {
        int num1;
        cout << "Enter the first number: ";
        cin >> num1;
        
        int num2;
        cout << "Enter the second number: ";
        cin >> num2;
        
        if (num2 == 0) {
            throw 0;
        }
        
        cout << "Result: " << num1 / num2; 
    }
    catch (int x) {
        cout << "Division by zero!";
    }
}
```

This results in the output of "Division by zero!" instead of a program crash when `0` is entered as the second number. In our case, we catch exceptions of type integer only. You can specify that your catch block handles any type of exception by adding an ellipsis `...` between the parentheses of `catch`:

```cpp
try {
    // code
} catch (...) {
    // code to handle exceptions
}
```

## Example: Handling User Input for a Menu

Here's how to handle user input for a digital menu by throwing an exception if the input index is out of the valid range of the menu items. You need to output "404 - not found" for invalid indices.

```cpp
#include <iostream>
using namespace std;

int main() {
    string menu[] = {"fruits", "chicken", "fish", "cake"};
    const int menuSize = sizeof(menu) / sizeof(menu[0]); // Size of the menu array

    try {
        int x;
        cin >> x;

        // Check if the index is within the valid range
        if (x < 0 || x >= menuSize) {
            throw 404; // Throwing an integer exception for out-of-range index
        }

        // Output the menu item if index is valid
        cout << menu[x] << endl;
    }
    catch (int e) {
        // Handling the exception
        if (e == 404) {
            cout << "404 - not found" << endl; // Output error message
        }
    }

    return 0;
}
```

### Explanation:

1. **Menu Array**:
   - `string menu[] = {"fruits", "chicken", "fish", "cake"};`: Array of menu items.
   - `const int menuSize = sizeof(menu) / sizeof(menu[0]);`: Calculate the number of items in the menu.

2. **User Input**:
   - `cin >> x;`: Read the user's input.

3. **Exception Handling**:
   - **Throwing an Exception**: If the input index `x` is less than 0 or greater than or equal to `menuSize`, `throw 404;` throws an exception with the code `404`.
   - **Catching the Exception**: The `catch (int e)` block catches the exception. If the exception code is `404`, it prints "404 - not found".

4. **Valid Index**:
   - If the index is within the valid range, the corresponding menu item is output using `cout << menu[x] << endl;`.

This approach ensures that invalid indices are handled gracefully and the user receives an appropriate error message.

Fill in the missing part to catch every kind of exception in the catch block:

```cpp
try {
    // ...some code
} catch (...) {
    // handle all exceptions
}
```
